Workbook

Sheet Instrucciones
A1: QUINIELA MUNDIAL DE FÚTBOL 2026 - 100% AUTOMATIZADA
A3: La Copa Mundial de la FIFA 26™ tendrá 48 equipos divididos en doce grupos con cuatro equipos cada uno.
A5: Los dos primeros de cada grupo y los ocho mejores terceros avanzarán a los dieciseisavos de final.
A7: Los equipos que lleguen a la final del 19 de julio habrán disputado ocho partidos, uno más que en Catar 2022.
A9: El nuevo esquema establece que los equipos que lleguen a la final, a jugarse el domingo 19 de julio, tendrán que haber atravesado ocho partidos, uno más de los disputados en la última Copa Mundial de la FIFA 2022™, en Catar.
A11: CÓMO FUNCIONA:
A13: 1. Pestaña 'Grupos': Ingresa los resultados. Las tablas se calculan en tiempo real.
A14: 2. Pestaña 'Eliminatorias': Al ir llenando, los nombres se auto-completan.
A15: 3. Puedes empezar a llenar y los líderes de cada grupo aparecerán de inmediato.
A16: 4. Guarda tu quiniela con tu nombre y apellido. Ejemplo: Quiniela_Cristiano_Ronaldo.xlsx, Quiniela_Lionel_Messi.xlsx
A18: Sistema de Puntuación
A20: Fase de Grupos:
... A50: salvador.velasco@gmail.com

Sheet Grupos
A1: PARTIDOS DE GRUPOS
A4: ID | B4: Grupo | C4: Equipo 1 | D4: Goles | E4: vs | F4: Goles | G4: Equipo 2 | H4: Estado | I4: Fecha y Hora | K4: Grupo | L4: Equipo | M4: PJ | N4: PG | O4: PE | P4: PP | Q4: GF | R4: GC | S4: DIF | T4: PTS | U4: SCORE TIEBREAK
A5: GRUPO A
C6: México | D6: 3 | E6: - | F6: 0 | G6: Sudáfrica | H6: =IF(AND(ISNUMBER(D6),ISNUMBER(F6)),"Ok","") | I6: Jueves, 11 de junio 2026 - 13:00 | K6: A | L6: México | M6: =IF(ISNUMBER(D6),1,0)+IF(ISNUMBER(D8),1,0)+IF(ISNUMBER(F10),1,0) | N6: =IF(AND(ISNUMBER(D6),ISNUMBER(F6),D6>F6),1,0)+IF(AND(ISNUMBER(D8),ISNUMBER(F8),D8>F8),1,0)+IF(AND(ISNUMBER(F10),ISNUMBER(D10),F10>D10),1,0) | O6: =IF(AND(ISNUMBER(D6),ISNUMBER(F6),D6=F6),1,0)+IF(AND(ISNUMBER(D8),ISNUMBER(F8),D8=F8),1,0)+IF(AND(ISNUMBER(F10),ISNUMBER(D10),F10=D10),1,0) | P6: =IF(AND(ISNUMBER(D6),ISNUMBER(F6),D6<F6),1,0)+IF(AND(ISNUMBER(D8),ISNUMBER(F8),D8<F8),1,0)+IF(AND(ISNUMBER(F10),ISNUMBER(D10),F10<D10),1,0) | Q6: =IF(ISNUMBER(D6),D6,0)+IF(ISNUMBER(D8),D8,0)+IF(ISNUMBER(F10),F10,0) | R6: =IF(ISNUMBER(F6),F6,0)+IF(ISNUMBER(F8),F8,0)+IF(ISNUMBER(D10),D10,0) | S6: =P6-Q6 | T6: =M6*3+N6 | U6: =S6*100000000 + (R6+100)*100000 + P6*1000 + IFERROR(VLOOKUP(K6, RankingFIFA!$A$1:$B$48, 2, FALSE), 0)
C7: Corea del Sur | D7: 1 | E7: - | F7: 2 | G7: Chequia | H7: =IF(AND(ISNUMBER(D7),ISNUMBER(F7)),"Ok","") | I7: Jueves, 11 de junio 2026 - 20:00 | K7: A | L7: Sudáfrica | M7: =IF(ISNUMBER(F6),1,0)+IF(ISNUMBER(D9),1,0)+IF(ISNUMBER(D11),1,0) | N7: =IF(AND(ISNUMBER(F6),ISNUMBER(D6),F6>D6),1,0)+IF(AND(ISNUMBER(D9),ISNUMBER(F9),D9>F9),1,0)+IF(AND(ISNUMBER(D11),ISNUMBER(F11),D11>F11),1,0) | O7: =IF(AND(ISNUMBER(F6),ISNUMBER(D6),F6=D6),1,0)+IF(AND(ISNUMBER(D9),ISNUMBER(F9),D9=F9),1,0)+IF(AND(ISNUMBER(D11),ISNUMBER(F11),D11=F11),1,0) | P7: =IF(AND(ISNUMBER(F6),ISNUMBER(D6),F6<D6),1,0)+IF(AND(ISNUMBER(D9),ISNUMBER(F9),D9<F9),1,0)+IF(AND(ISNUMBER(D11),ISNUMBER(F11),D11<F11),1,0) | Q7: =IF(ISNUMBER(F6),F6,0)+IF(ISNUMBER(D9),D9,0)+IF(ISNUMBER(D11),D11,0) | R7: =IF(ISNUMBER(D6),D6,0)+IF(ISNUMBER(F9),F9,0)+IF(ISNUMBER(F11),F11,0) | S7: =P7-Q7 | T7: =M7*3+N7 | U7: =S7*100000000 + (R7+100)*100000 + P7*1000 + IFERROR(VLOOKUP(K7, RankingFIFA!$A$1:$B$48, 2, FALSE), 0)
C8: México | D8: 2 | E8: - | F8: 1 | G8: Corea del Sur | H8: =IF(AND(ISNUMBER(D8),ISNUMBER(F8)),"Ok","") | I8: Jueves, 18 de junio 2026 - 19:00 | K8: A | L8: Corea del Sur | M8: =IF(ISNUMBER(D7),1,0)+IF(ISNUMBER(F8),1,0)+IF(ISNUMBER(F11),1,0) | N8: =IF(AND(ISNUMBER(D7),ISNUMBER(F7),D7>F7),1,0)+IF(AND(ISNUMBER(F8),ISNUMBER(D8),F8>D8),1,0)+IF(AND(ISNUMBER(F11),ISNUMBER(D11),F11>D11),1,0) | O8: =IF(AND(ISNUMBER(D7),ISNUMBER(F7),D7=F7),1,0)+IF(AND(ISNUMBER(F8),ISNUMBER(D8),F8=D8),1,0)+IF(AND(ISNUMBER(F11),ISNUMBER(D11),F11=D11),1,0) | P8: =IF(AND(ISNUMBER(D7),ISNUMBER(F7),D7<F7),1,0)+IF(AND(ISNUMBER(F8),ISNUMBER(D8),F8<D8),1,0)+IF(AND(ISNUMBER(F11),ISNUMBER(D11),F11<D11),1,0) | Q8: =IF(ISNUMBER(D7),D7,0)+IF(ISNUMBER(F8),F8,0)+IF(ISNUMBER(F11),F11,0) | R8: =IF(ISNUMBER(F7),F7,0)+IF(ISNUMBER(D8),D8,0)+IF(ISNUMBER(D11),D11,0) | S8: =P8-Q8 | T8: =M8*3+N8 | U8: =S8*100000000 + (R8+100)*100000 + P8*1000 + IFERROR(VLOOKUP(K8, RankingFIFA!$A$1:$B$48, 2, FALSE), 0)
C9: Sudáfrica | D9: 0 | E9: - | F9: 3 | G9: Chequia | H9: =IF(AND(ISNUMBER(D9),ISNUMBER(F9)),"Ok","") | I9: Jueves, 18 de junio 2026 - 10:00 | K9: A | L9: Chequia | M9: =IF(ISNUMBER(F7),1,0)+IF(ISNUMBER(F9),1,0)+IF(ISNUMBER(D10),1,0) | N9: =IF(AND(ISNUMBER(F7),ISNUMBER(D7),F7>D7),1,0)+IF(AND(ISNUMBER(F9),ISNUMBER(D9),F9>D9),1,0)+IF(AND(ISNUMBER(D10),ISNUMBER(F10),D10>F10),1,0) | O9: =IF(AND(ISNUMBER(F7),ISNUMBER(D7),F7=D7),1,0)+IF(AND(ISNUMBER(F9),ISNUMBER(D9),F9=D9),1,0)+IF(AND(ISNUMBER(D10),ISNUMBER(F10),D10=F10),1,0) | P9: =IF(AND(ISNUMBER(F7),ISNUMBER(D7),F7<D7),1,0)+IF(AND(ISNUMBER(F9),ISNUMBER(D9),F9<D9),1,0)+IF(AND(ISNUMBER(D10),ISNUMBER(F10),D10<F10),1,0) | Q9: =IF(ISNUMBER(F7),F7,0)+IF(ISNUMBER(F9),F9,0)+IF(ISNUMBER(D10),D10,0) | R9: =IF(ISNUMBER(D7),D7,0)+IF(ISNUMBER(D9),D9,0)+IF(ISNUMBER(F10),F10,0) | S9: =P9-Q9 | T9: =M9*3+N9 | U9: =S9*100000000 + (R9+100)*100000 + P9*1000 + IFERROR(VLOOKUP(K9, RankingFIFA!$A$1:$B$48, 2, FALSE), 0)
C10: Chequia | D10: 3 | E10: - | F10: 1 | G10: México | H10: =IF(AND(ISNUMBER(D10),ISNUMBER(F10)),"Ok","") | I10: Miércoles, 24 de junio 2026 - 19:00
C11: Sudáfrica | D11: 3 | E11: - | F11: 0 | G11: Corea del Sur | H11: =IF(AND(ISNUMBER(D11),ISNUMBER(F11)),"Ok","") | I11: Miércoles, 24 de junio 2026 - 19:00
K12: B | L12: Canadá | M12: =IF(ISNUMBER(D14),1,0)+IF(ISNUMBER(D16),1,0)+IF(ISNUMBER(F18),1,0) | N12: =IF(AND(ISNUMBER(D14),ISNUMBER(F14),D14>F14),1,0)+IF(AND(ISNUMBER(D16),ISNUMBER(F16),D16>F16),1,0)+IF(AND(ISNUMBER(F18),ISNUMBER(D18),F18>D18),1,0) | O12: =IF(AND(ISNUMBER(D14),ISNUMBER(F14),D14=F14),1,0)+IF(AND(ISNUMBER(D16),ISNUMBER(F16),D16=F16),1,0)+IF(AND(ISNUMBER(F18),ISNUMBER(D18),F18=D18),1,0) | P12: =IF(AND(ISNUMBER(D14),ISNUMBER(F14),D14<F14),1,0)+IF(AND(ISNUMBER(D16),ISNUMBER(F16),D16<F16),1,0)+IF(AND(ISNUMBER(F18),ISNUMBER(D18),F18<D18),1,0) | Q12: =IF(ISNUMBER(D14),D14,0)+IF(ISNUMBER(D16),D16,0)+IF(ISNUMBER(F18),F18,0) | R12: =IF(ISNUMBER(F14),F14,0)+IF(ISNUMBER(F16),F16,0)+IF(ISNUMBER(D18),D18,0) | S12: =P12-Q12 | T12: =M12*3+N12 | U12: =S12*100000000 + (R12+100)*100000 + P12*1000 + IFERROR(VLOOKUP(K12, RankingFIFA!$A$1:$B$48, 2, FALSE), 0)
A13: GRUPO B | K13: B | L13: Bosnia y Herze. | M13: =IF(ISNUMBER(F14),1,0)+IF(ISNUMBER(D17),1,0)+IF(ISNUMBER(D19),1,0) | N13: =IF(AND(ISNUMBER(F14),ISNUMBER(D14),F14>D14),1,0)+IF(AND(ISNUMBER(D17),ISNUMBER(F17),D17>F17),1,0)+IF(AND(ISNUMBER(D19),ISNUMBER(F19),D19>F19),1,0) | O13: =IF(AND(ISNUMBER(F14),ISNUMBER(D14),F14=D14),1,0)+IF(AND(ISNUMBER(D17),ISNUMBER(F17),D17=F17),1,0)+IF(AND(ISNUMBER(D19),ISNUMBER(F19),D19=F19),1,0) | P13: =IF(AND(ISNUMBER(F14),ISNUMBER(D14),F14<D14),1,0)+IF(AND(ISNUMBER(D17),ISNUMBER(F17),D17<F17),1,0)+IF(AND(ISNUMBER(D19),ISNUMBER(F19),D19<F19),1,0) | Q13: =IF(ISNUMBER(F14),F14,0)+IF(ISNUMBER(D17),D17,0)+IF(ISNUMBER(D19),D19,0) | R13: =IF(ISNUMBER(D14),D14,0)+IF(ISNUMBER(F17),F17,0)+IF(ISNUMBER(F19),F19,0) | S13: =P13-Q13 | T13: =M13*3+N13 | U13: =S13*100000000 + (R13+100)*100000 + P13*1000 + IFERROR(VLOOKUP(K13, RankingFIFA!$A$1:$B$48, 2, FALSE), 0)
C14: Canadá | D14: 0 | E14: - | F14: 2 | G14: Bosnia y Herze. | H14: =IF(AND(ISNUMBER(D14),ISNUMBER(F14)),"Ok","") | I14: Viernes, 12 de junio 2026 - 13:00 | K14: B | L14: Qatar | M14: =IF(ISNUMBER(D15),1,0)+IF(ISNUMBER(F16),1,0)+IF(ISNUMBER(F19),1,0) | N14: =IF(AND(ISNUMBER(D15),ISNUMBER(F15),D15>F15),1,0)+IF(AND(ISNUMBER(F16),ISNUMBER(D16),F16>D16),1,0)+IF(AND(ISNUMBER(F19),ISNUMBER(D19),F19>D19),1,0) | O14: =IF(AND(ISNUMBER(D15),ISNUMBER(F15),D15=F15),1,0)+IF(AND(ISNUMBER(F16),ISNUMBER(D16),F16=D16),1,0)+IF(AND(ISNUMBER(F19),ISNUMBER(D19),F19=D19),1,0) | P14: =IF(AND(ISNUMBER(D15),ISNUMBER(F15),D15<F15),1,0)+IF(AND(ISNUMBER(F16),ISNUMBER(D16),F16<D16),1,0)+IF(AND(ISNUMBER(F19),ISNUMBER(D19),F19<D19),1,0) | Q14: =IF(ISNUMBER(D15),D15,0)+IF(ISNUMBER(F16),F16,0)+IF(ISNUMBER(F19),F19,0) | R14: =IF(ISNUMBER(F15),F15,0)+IF(ISNUMBER(D16),D16,0)+IF(ISNUMBER(D19),D19,0) | S14: =P14-Q14 | T14: =M14*3+N14 | U14: =S14*100000000 + (R14+100)*100000 + P14*1000 + IFERROR(VLOOKUP(K14, RankingFIFA!$A$1:$B$48, 2, FALSE), 0)
C15: Qatar | D15: 0 | E15: - | F15: 2 | G15: Suiza | H15: =IF(AND(ISNUMBER(D15),ISNUMBER(F15)),"Ok","") | I15: Sábado, 13 de junio 2026 - 13:00 | K15: B | L15: Suiza | M15: =IF(ISNUMBER(F15),1,0)+IF(ISNUMBER(F17),1,0)+IF(ISNUMBER(D18),1,0) | N15: =IF(AND(ISNUMBER(F15),ISNUMBER(D15),F15>D15),1,0)+IF(AND(ISNUMBER(F17),ISNUMBER(D17),F17>D17),1,0)+IF(AND(ISNUMBER(D18),ISNUMBER(F18),D18>F18),1,0) | O15: =IF(AND(ISNUMBER(F15),ISNUMBER(D15),F15=D15),1,0)+IF(AND(ISNUMBER(F17),ISNUMBER(D17),F17=D17),1,0)+IF(AND(ISNUMBER(D18),ISNUMBER(F18),D18=F18),1,0) | P15: =IF(AND(ISNUMBER(F15),ISNUMBER(D15),F15<D15),1,0)+IF(AND(ISNUMBER(F17),ISNUMBER(D17),F17<D17),1,0)+IF(AND(ISNUMBER(D18),ISNUMBER(F18),D18<F18),1,0) | Q15: =IF(ISNUMBER(F15),F15,0)+IF(ISNUMBER(F17),F17,0)+IF(ISNUMBER(D18),D18,0) | R15: =IF(ISNUMBER(D15),D15,0)+IF(ISNUMBER(D17),D17,0)+IF(ISNUMBER(F18),F18,0) | S15: =P15-Q15 | T15: =M15*3+N15 | U15: =S15*100000000 + (R15+100)*100000 + P15*1000 + IFERROR(VLOOKUP(K15, RankingFIFA!$A$1:$B$48, 2, FALSE), 0)
C16: Canadá | D16: 1 | E16: - | F16: 2 | G16: Qatar | H16: =IF(AND(ISNUMBER(D16),ISNUMBER(F16)),"Ok","") | I16: Jueves, 18 de junio 2026 - 16:00
C17: Bosnia y Herze. | D17: 0 | E17: - | F17: 2 | G17: Suiza | H17: =IF(AND(ISNUMBER(D17),ISNUMBER(F17)),"Ok","") | I17: Jueves, 18 de junio 2026 - 13:00
C18: Suiza | D18: 2 | E18: - | F18: 1 | G18: Canadá | H18: =IF(AND(ISNUMBER(D18),ISNUMBER(F18)),"Ok","") | I18: Miércoles, 24 de junio 2026 - 13:00 | K18: C | L18: Brasil | M18: =IF(ISNUMBER(D22),1,0)+IF(ISNUMBER(D24),1,0)+IF(ISNUMBER(F26),1,0) | N18: =IF(AND(ISNUMBER(D22),ISNUMBER(F22),D22>F22),1,0)+IF(AND(ISNUMBER(D24),ISNUMBER(F24),D24>F24),1,0)+IF(AND(ISNUMBER(F26),ISNUMBER(D26),F26>D26),1,0) | O18: =IF(AND(ISNUMBER(D22),ISNUMBER(F22),D22=F22),1,0)+IF(AND(ISNUMBER(D24),ISNUMBER(F24),D24=F24),1,0)+IF(AND(ISNUMBER(F26),ISNUMBER(D26),F26=D26),1,0) | P18: =IF(AND(ISNUMBER(D22),ISNUMBER(F22),D22<F22),1,0)+IF(AND(ISNUMBER(D24),ISNUMBER(F24),D24<F24),1,0)+IF(AND(ISNUMBER(F26),ISNUMBER(D26),F26<D26),1,0) | Q18: =IF(ISNUMBER(D22),D22,0)+IF(ISNUMBER(D24),D24,0)+IF(ISNUMBER(F26),F26,0) | R18: =IF(ISNUMBER(F22),F22,0)+IF(ISNUMBER(F24),F24,0)+IF(ISNUMBER(D26),D26,0) | S18: =P18-Q18 | T18: =M18*3+N18 | U18: =S18*100000000 + (R18+100)*100000 + P18*1000 + IFERROR(VLOOKUP(K18, RankingFIFA!$A$1:$B$48, 2, FALSE), 0)
C19: Bosnia y Herze. | D19: 2 | E19: - | F19: 1 | G19: Qatar | H19: =IF(AND(ISNUMBER(D19),ISNUMBER(F19)),"Ok","") | I19: Miércoles, 24 de junio 2026 - 13:00 | K19: C | L19: Marruecos | M19: =IF(ISNUMBER(F22),1,0)+IF(ISNUMBER(D25),1,0)+IF(ISNUMBER(D27),1,0) | N19: =IF(AND(ISNUMBER(F22),ISNUMBER(D22),F22>D22),1,0)+IF(AND(ISNUMBER(D25),ISNUMBER(F25),D25>F25),1,0)+IF(AND(ISNUMBER(D27),ISNUMBER(F27),D27>F27),1,0) | O19: =IF(AND(ISNUMBER(F22),ISNUMBER(D22),F22=D22),1,0)+IF(AND(ISNUMBER(D25),ISNUMBER(F25),D25=F25),1,0)+IF(AND(ISNUMBER(D27),ISNUMBER(F27),D27=F27),1,0) | P19: =IF(AND(ISNUMBER(F22),ISNUMBER(D22),F22<D22),1,0)+IF(AND(ISNUMBER(D25),ISNUMBER(F25),D25<F25),1,0)+IF(AND(ISNUMBER(D27),ISNUMBER(F27),D27<F27),1,0) | Q19: =IF(ISNUMBER(F22),F22,0)+IF(ISNUMBER(D25),D25,0)+IF(ISNUMBER(D27),D27,0) | R19: =IF(ISNUMBER(D22),D22,0)+IF(ISNUMBER(F25),F25,0)+IF(ISNUMBER(F27),F27,0) | S19: =P19-Q19 | T19: =M19*3+N19 | U19: =S19*100000000 + (R19+100)*100000 + P19*1000 + IFERROR(VLOOKUP(K19, RankingFIFA!$A$1:$B$48, 2, FALSE), 0)
K20: C | L20: Haití | M20: =IF(ISNUMBER(D23),1,0)+IF(ISNUMBER(F24),1,0)+IF(ISNUMBER(F27),1,0) | N20: =IF(AND(ISNUMBER(D23),ISNUMBER(F23),D23>F23),1,0)+IF(AND(ISNUMBER(F24),ISNUMBER(D24),F24>D24),1,0)+IF(AND(ISNUMBER(F27),ISNUMBER(D27),F27>D27),1,0) | O20: =IF(AND(ISNUMBER(D23),ISNUMBER(F23),D23=F23),1,0)+IF(AND(ISNUMBER(F24),ISNUMBER(D24),F24=D24),1,0)+IF(AND(ISNUMBER(F27),ISNUMBER(D27),F27=D27),1,0) | P20: =IF(AND(ISNUMBER(D23),ISNUMBER(F23),D23<F23),1,0)+IF(AND(ISNUMBER(F24),ISNUMBER(D24),F24<D24),1,0)+IF(AND(ISNUMBER(F27),ISNUMBER(D27),F27<D27),1,0) | Q20: =IF(ISNUMBER(D23),D23,0)+IF(ISNUMBER(F24),F24,0)+IF(ISNUMBER(F27),F27,0) | R20: =IF(ISNUMBER(F23),F23,0)+IF(ISNUMBER(D24),D24,0)+IF(ISNUMBER(D27),D27,0) | S20: =P20-Q20 | T20: =M20*3+N20 | U20: =S20*100000000 + (R20+100)*100000 + P20*1000 + IFERROR(VLOOKUP(K20, RankingFIFA!$A$1:$B$48, 2, FALSE), 0)
A21: GRUPO C | K21: C | L21: Escocia | M21: =IF(ISNUMBER(F23),1,0)+IF(ISNUMBER(F25),1,0)+IF(ISNUMBER(D26),1,0) | N21: =IF(AND(ISNUMBER(F23),ISNUMBER(D23),F23>D23),1,0)+IF(AND(ISNUMBER(F25),ISNUMBER(D25),F25>D25),1,0)+IF(AND(ISNUMBER(D26),ISNUMBER(F26),D26>F26),1,0) | O21: =IF(AND(ISNUMBER(F23),ISNUMBER(D23),F23=D23),1,0)+IF(AND(ISNUMBER(F25),ISNUMBER(D25),F25=D25),1,0)+IF(AND(ISNUMBER(D26),ISNUMBER(F26),D26=F26),1,0) | P21: =IF(AND(ISNUMBER(F23),ISNUMBER(D23),F23<D23),1,0)+IF(AND(ISNUMBER(F25),ISNUMBER(D25),F25<D25),1,0)+IF(AND(ISNUMBER(D26),ISNUMBER(F26),D26<F26),1,0) | Q21: =IF(ISNUMBER(F23),F23,0)+IF(ISNUMBER(F25),F25,0)+IF(ISNUMBER(D26),D26,0) | R21: =IF(ISNUMBER(D23),D23,0)+IF(ISNUMBER(D25),D25,0)+IF(ISNUMBER(F26),F26,0) | S21: =P21-Q21 | T21: =M21*3+N21 | U21: =S21*100000000 + (R21+100)*100000 + P21*1000 + IFERROR(VLOOKUP(K21, RankingFIFA!$A$1:$B$48, 2, FALSE), 0)
C22: Brasil | D22: 1 | E22: - | F22: 2 | G22: Marruecos | H22: =IF(AND(ISNUMBER(D22),ISNUMBER(F22)),"Ok","") | I22: Sábado, 13 de junio 2026 - 16:00
C23: Haití | D23: 2 | E23: - | F23: 1 | G23: Escocia | H23: =IF(AND(ISNUMBER(D23),ISNUMBER(F23)),"Ok","") | I23: Sábado, 13 de junio 2026 - 19:00
C24: Brasil | D24: 2 | E24: - | F24: 0 | G24: Haití | H24: =IF(AND(ISNUMBER(D24),ISNUMBER(F24)),"Ok","") | I24: Viernes, 19 de junio 2026 - 19:00 | K24: D | L24: Estados Unidos | M24: =IF(ISNUMBER(D30),1,0)+IF(ISNUMBER(D32),1,0)+IF(ISNUMBER(F34),1,0) | N24: =IF(AND(ISNUMBER(D30),ISNUMBER(F30),D30>F30),1,0)+IF(AND(ISNUMBER(D32),ISNUMBER(F32),D32>F32),1,0)+IF(AND(ISNUMBER(F34),ISNUMBER(D34),F34>D34),1,0) | O24: =IF(AND(ISNUMBER(D30),ISNUMBER(F30),D30=F30),1,0)+IF(AND(ISNUMBER(D32),ISNUMBER(F32),D32=F32),1,0)+IF(AND(ISNUMBER(F34),ISNUMBER(D34),F34=D34),1,0) | P24: =IF(AND(ISNUMBER(D30),ISNUMBER(F30),D30<F30),1,0)+IF(AND(ISNUMBER(D32),ISNUMBER(F32),D32<F32),1,0)+IF(AND(ISNUMBER(F34),ISNUMBER(D34),F34<D34),1,0) | Q24: =IF(ISNUMBER(D30),D30,0)+IF(ISNUMBER(D32),D32,0)+IF(ISNUMBER(F34),F34,0) | R24: =IF(ISNUMBER(F30),F30,0)+IF(ISNUMBER(F32),F32,0)+IF(ISNUMBER(D34),D34,0) | S24: =P24-Q24 | T24: =M24*3+N24 | U24: =S24*100000000 + (R24+100)*100000 + P24*1000 + IFERROR(VLOOKUP(K24, RankingFIFA!$A$1:$B$48, 2, FALSE), 0)
C25: Marruecos | D25: 0 | E25: - | F25: 2 | G25: Escocia | H25: =IF(AND(ISNUMBER(D25),ISNUMBER(F25)),"Ok","") | I25: Viernes, 19 de junio 2026 - 16:00 | K25: D | L25: Paraguay | M25: =IF(ISNUMBER(F30),1,0)+IF(ISNUMBER(D33),1,0)+IF(ISNUMBER(D35),1,0) | N25: =IF(AND(ISNUMBER(F30),ISNUMBER(D30),F30>D30),1,0)+IF(AND(ISNUMBER(D33),ISNUMBER(F33),D33>F33),1,0)+IF(AND(ISNUMBER(D35),ISNUMBER(F35),D35>F35),1,0) | O25: =IF(AND(ISNUMBER(F30),ISNUMBER(D30),F30=D30),1,0)+IF(AND(ISNUMBER(D33),ISNUMBER(F33),D33=F33),1,0)+IF(AND(ISNUMBER(D35),ISNUMBER(F35),D35=F35),1,0) | P25: =IF(AND(ISNUMBER(F30),ISNUMBER(D30),F30<D30),1,0)+IF(AND(ISNUMBER(D33),ISNUMBER(F33),D33<F33),1,0)+IF(AND(ISNUMBER(D35),ISNUMBER(F35),D35<F35),1,0) | Q25: =IF(ISNUMBER(F30),F30,0)+IF(ISNUMBER(D33),D33,0)+IF(ISNUMBER(D35),D35,0) | R25: =IF(ISNUMBER(D30),D30,0)+IF(ISNUMBER(F33),F33,0)+IF(ISNUMBER(F35),F35,0) | S25: =P25-Q25 | T25: =M25*3+N25 | U25: =S25*100000000 + (R25+100)*100000 + P25*1000 + IFERROR(VLOOKUP(K25, RankingFIFA!$A$1:$B$48, 2, FALSE), 0)
C26: Escocia | D26: 0 | E26: - | F26: 2 | G26: Brasil | H26: =IF(AND(ISNUMBER(D26),ISNUMBER(F26)),"Ok","") | I26: Miércoles, 24 de junio 2026 - 16:00 | K26: D | L26: Australia | M26: =IF(ISNUMBER(D31),1,0)+IF(ISNUMBER(F32),1,0)+IF(ISNUMBER(F35),1,0) | N26: =IF(AND(ISNUMBER(D31),ISNUMBER(F31),D31>F31),1,0)+IF(AND(ISNUMBER(F32),ISNUMBER(D32),F32>D32),1,0)+IF(AND(ISNUMBER(F35),ISNUMBER(D35),F35>D35),1,0) | O26: =IF(AND(ISNUMBER(D31),ISNUMBER(F31),D31=F31),1,0)+IF(AND(ISNUMBER(F32),ISNUMBER(D32),F32=D32),1,0)+IF(AND(ISNUMBER(F35),ISNUMBER(D35),F35=D35),1,0) | P26: =IF(AND(ISNUMBER(D31),ISNUMBER(F31),D31<F31),1,0)+IF(AND(ISNUMBER(F32),ISNUMBER(D32),F32<D32),1,0)+IF(AND(ISNUMBER(F35),ISNUMBER(D35),F35<D35),1,0) | Q26: =IF(ISNUMBER(D31),D31,0)+IF(ISNUMBER(F32),F32,0)+IF(ISNUMBER(F35),F35,0) | R26: =IF(ISNUMBER(F31),F31,0)+IF(ISNUMBER(D32),D32,0)+IF(ISNUMBER(D35),D35,0) | S26: =P26-Q26 | T26: =M26*3+N26 | U26: =S26*100000000 + (R26+100)*100000 + P26*1000 + IFERROR(VLOOKUP(K26, RankingFIFA!$A$1:$B$48, 2, FALSE), 0)
C27: Marruecos | D27: 1 | E27: - | F27: 2 | G27: Haití | H27: =IF(AND(ISNUMBER(D27),ISNUMBER(F27)),"Ok","") | I27: Miércoles, 24 de junio 2026 - 16:00 | K27: D | L27: Turquía | M27: =IF(ISNUMBER(F31),1,0)+IF(ISNUMBER(F33),1,0)+IF(ISNUMBER(D34),1,0) | N27: =IF(AND(ISNUMBER(F31),ISNUMBER(D31),F31>D31),1,0)+IF(AND(ISNUMBER(F33),ISNUMBER(D33),F33>D33),1,0)+IF(AND(ISNUMBER(D34),ISNUMBER(F34),D34>F34),1,0) | O27: =IF(AND(ISNUMBER(F31),ISNUMBER(D31),F31=D31),1,0)+IF(AND(ISNUMBER(F33),ISNUMBER(D33),F33=D33),1,0)+IF(AND(ISNUMBER(D34),ISNUMBER(F34),D34=F34),1,0) | P27: =IF(AND(ISNUMBER(F31),ISNUMBER(D31),F31<D31),1,0)+IF(AND(ISNUMBER(F33),ISNUMBER(D33),F33<D33),1,0)+IF(AND(ISNUMBER(D34),ISNUMBER(F34),D34<F34),1,0) | Q27: =IF(ISNUMBER(F31),F31,0)+IF(ISNUMBER(F33),F33,0)+IF(ISNUMBER(D34),D34,0) | R27: =IF(ISNUMBER(D31),D31,0)+IF(ISNUMBER(D33),D33,0)+IF(ISNUMBER(F34),F34,0) | S27: =P27-Q27 | T27: =M27*3+N27 | U27: =S27*100000000 + (R27+100)*100000 + P27*1000 + IFERROR(VLOOKUP(K27, RankingFIFA!$A$1:$B$48, 2, FALSE), 0)
A29: GRUPO D
C30: Estados Unidos | D30: 1 | E30: - | F30: 1 | G30: Paraguay | H30: =IF(AND(ISNUMBER(D30),ISNUMBER(F30)),"Ok","") | I30: Viernes, 12 de junio 2026 - 19:00 | K30: E | L30: Alemania | M30: =IF(ISNUMBER(D38),1,0)+IF(ISNUMBER(D40),1,0)+IF(ISNUMBER(F42),1,0) | N30: =IF(AND(ISNUMBER(D38),ISNUMBER(F38),D38>F38),1,0)+IF(AND(ISNUMBER(D40),ISNUMBER(F40),D40>F40),1,0)+IF(AND(ISNUMBER(F42),ISNUMBER(D42),F42>D42),1,0) | O30: =IF(AND(ISNUMBER(D38),ISNUMBER(F38),D38=F38),1,0)+IF(AND(ISNUMBER(D40),ISNUMBER(F40),D40=F40),1,0)+IF(AND(ISNUMBER(F42),ISNUMBER(D42),F42=D42),1,0) | P30: =IF(AND(ISNUMBER(D38),ISNUMBER(F38),D38<F38),1,0)+IF(AND(ISNUMBER(D40),ISNUMBER(F40),D40<F40),1,0)+IF(AND(ISNUMBER(F42),ISNUMBER(D42),F42<D42),1,0) | Q30: =IF(ISNUMBER(D38),D38,0)+IF(ISNUMBER(D40),D40,0)+IF(ISNUMBER(F42),F42,0) | R30: =IF(ISNUMBER(F38),F38,0)+IF(ISNUMBER(F40),F40,0)+IF(ISNUMBER(D42),D42,0) | S30: =P30-Q30 | T30: =M30*3+N30 | U30: =S30*100000000 + (R30+100)*100000 + P30*1000 + IFERROR(VLOOKUP(K30, RankingFIFA!$A$1:$B$48, 2, FALSE), 0)
C31: Australia | D31: 1 | E31: - | F31: 0 | G31: Turquía | H31: =IF(AND(ISNUMBER(D31),ISNUMBER(F31)),"Ok","") | I31: Sábado, 13 de junio 2026 - 22:00 | K31: E | L31: Curaçao | M31: =IF(ISNUMBER(F38),1,0)+IF(ISNUMBER(D41),1,0)+IF(ISNUMBER(D43),1,0) | N31: =IF(AND(ISNUMBER(F38),ISNUMBER(D38),F38>D38),1,0)+IF(AND(ISNUMBER(D41),ISNUMBER(F41),D41>F41),1,0)+IF(AND(ISNUMBER(D43),ISNUMBER(F43),D43>F43),1,0) | O31: =IF(AND(ISNUMBER(F38),ISNUMBER(D38),F38=D38),1,0)+IF(AND(ISNUMBER(D41),ISNUMBER(F41),D41=F41),1,0)+IF(AND(ISNUMBER(D43),ISNUMBER(F43),D43=F43),1,0) | P31: =IF(AND(ISNUMBER(F38),ISNUMBER(D38),F38<D38),1,0)+IF(AND(ISNUMBER(D41),ISNUMBER(F41),D41<F41),1,0)+IF(AND(ISNUMBER(D43),ISNUMBER(F43),D43<F43),1,0) | Q31: =IF(ISNUMBER(F38),F38,0)+IF(ISNUMBER(D41),D41,0)+IF(ISNUMBER(D43),D43,0) | R31: =IF(ISNUMBER(D38),D38,0)+IF(ISNUMBER(F41),F41,0)+IF(ISNUMBER(F43),F43,0) | S31: =P31-Q31 | T31: =M31*3+N31 | U31: =S31*100000000 + (R31+100)*100000 + P31*1000 + IFERROR(VLOOKUP(K31, RankingFIFA!$A$1:$B$48, 2, FALSE), 0)
C32: Estados Unidos | D32: 0 | E32: - | F32: 1 | G32: Australia | H32: =IF(AND(ISNUMBER(D32),ISNUMBER(F32)),"Ok","") | I32: Viernes, 19 de junio 2026 - 13:00 | K32: E | L32: Costa de Marfil | M32: =IF(ISNUMBER(D39),1,0)+IF(ISNUMBER(F40),1,0)+IF(ISNUMBER(F43),1,0) | N32: =IF(AND(ISNUMBER(D39),ISNUMBER(F39),D39>F39),1,0)+IF(AND(ISNUMBER(F40),ISNUMBER(D40),F40>D40),1,0)+IF(AND(ISNUMBER(F43),ISNUMBER(D43),F43>D43),1,0) | O32: =IF(AND(ISNUMBER(D39),ISNUMBER(F39),D39=F39),1,0)+IF(AND(ISNUMBER(F40),ISNUMBER(D40),F40=D40),1,0)+IF(AND(ISNUMBER(F43),ISNUMBER(D43),F43=D43),1,0) | P32: =IF(AND(ISNUMBER(D39),ISNUMBER(F39),D39<F39),1,0)+IF(AND(ISNUMBER(F40),ISNUMBER(D40),F40<D40),1,0)+IF(AND(ISNUMBER(F43),ISNUMBER(D43),F43<D43),1,0) | Q32: =IF(ISNUMBER(D39),D39,0)+IF(ISNUMBER(F40),F40,0)+IF(ISNUMBER(F43),F43,0) | R32: =IF(ISNUMBER(F39),F39,0)+IF(ISNUMBER(D40),D40,0)+IF(ISNUMBER(D43),D43,0) | S32: =P32-Q32 | T32: =M32*3+N32 | U32: =S32*100000000 + (R32+100)*100000 + P32*1000 + IFERROR(VLOOKUP(K32, RankingFIFA!$A$1:$B$48, 2, FALSE), 0)
C33: Paraguay | D33: 1 | E33: - | F33: 2 | G33: Turquía | H33: =IF(AND(ISNUMBER(D33),ISNUMBER(F33)),"Ok","") | I33: Viernes, 19 de junio 2026 - 22:00 | K33: E | L33: Ecuador | M33: =IF(ISNUMBER(F39),1,0)+IF(ISNUMBER(F41),1,0)+IF(ISNUMBER(D42),1,0) | N33: =IF(AND(ISNUMBER(F39),ISNUMBER(D39),F39>D39),1,0)+IF(AND(ISNUMBER(F41),ISNUMBER(D41),F41>D41),1,0)+IF(AND(ISNUMBER(D42),ISNUMBER(F42),D42>F42),1,0) | O33: =IF(AND(ISNUMBER(F39),ISNUMBER(D39),F39=D39),1,0)+IF(AND(ISNUMBER(F41),ISNUMBER(D41),F41=D41),1,0)+IF(AND(ISNUMBER(D42),ISNUMBER(F42),D42=F42),1,0) | P33: =IF(AND(ISNUMBER(F39),ISNUMBER(D39),F39<D39),1,0)+IF(AND(ISNUMBER(F41),ISNUMBER(D41),F41<D41),1,0)+IF(AND(ISNUMBER(D42),ISNUMBER(F42),D42<F42),1,0) | Q33: =IF(ISNUMBER(F39),F39,0)+IF(ISNUMBER(F41),F41,0)+IF(ISNUMBER(D42),D42,0) | R33: =IF(ISNUMBER(D39),D39,0)+IF(ISNUMBER(D41),D41,0)+IF(ISNUMBER(F42),F42,0) | S33: =P33-Q33 | T33: =M33*3+N33 | U33: =S33*100000000 + (R33+100)*100000 + P33*1000 + IFERROR(VLOOKUP(K33, RankingFIFA!$A$1:$B$48, 2, FALSE), 0)
C34: Turquía | D34: 1 | E34: - | F34: 3 | G34: Estados Unidos | H34: =IF(AND(ISNUMBER(D34),ISNUMBER(F34)),"Ok","") | I34: Jueves, 25 de junio 2026 - 20:00
C35: Paraguay | D35: 2 | E35: - | F35: 1 | G35: Australia | H35: =IF(AND(ISNUMBER(D35),ISNUMBER(F35)),"Ok","") | I35: Jueves, 25 de junio 2026 - 20:00
K36: F | L36: Países Bajos | M36: =IF(ISNUMBER(D46),1,0)+IF(ISNUMBER(D48),1,0)+IF(ISNUMBER(F50),1,0) | N36: =IF(AND(ISNUMBER(D46),ISNUMBER(F46),D46>F46),1,0)+IF(AND(ISNUMBER(D48),ISNUMBER(F48),D48>F48),1,0)+IF(AND(ISNUMBER(F50),ISNUMBER(D50),F50>D50),1,0) | O36: =IF(AND(ISNUMBER(D46),ISNUMBER(F46),D46=F46),1,0)+IF(AND(ISNUMBER(D48),ISNUMBER(F48),D48=F48),1,0)+IF(AND(ISNUMBER(F50),ISNUMBER(D50),F50=D50),1,0) | P36: =IF(AND(ISNUMBER(D46),ISNUMBER(F46),D46<F46),1,0)+IF(AND(ISNUMBER(D48),ISNUMBER(F48),D48<F48),1,0)+IF(AND(ISNUMBER(F50),ISNUMBER(D50),F50<D50),1,0) | Q36: =IF(ISNUMBER(D46),D46,0)+IF(ISNUMBER(D48),D48,0)+IF(ISNUMBER(F50),F50,0) | R36: =IF(ISNUMBER(F46),F46,0)+IF(ISNUMBER(F48),F48,0)+IF(ISNUMBER(D50),D50,0) | S36: =P36-Q36 | T36: =M36*3+N36 | U36: =S36*100000000 + (R36+100)*100000 + P36*1000 + IFERROR(VLOOKUP(K36, RankingFIFA!$A$1:$B$48, 2, FALSE), 0)
A37: GRUPO E | K37: F | L37: Japón | M37: =IF(ISNUMBER(F46),1,0)+IF(ISNUMBER(D49),1,0)+IF(ISNUMBER(D51),1,0) | N37: =IF(AND(ISNUMBER(F46),ISNUMBER(D46),F46>D46),1,0)+IF(AND(ISNUMBER(D49),ISNUMBER(F49),D49>F49),1,0)+IF(AND(ISNUMBER(D51),ISNUMBER(F51),D51>F51),1,0) | O37: =IF(AND(ISNUMBER(F46),ISNUMBER(D46),F46=D46),1,0)+IF(AND(ISNUMBER(D49),ISNUMBER(F49),D49=F49),1,0)+IF(AND(ISNUMBER(D51),ISNUMBER(F51),D51=F51),1,0) | P37: =IF(AND(ISNUMBER(F46),ISNUMBER(D46),F46<D46),1,0)+IF(AND(ISNUMBER(D49),ISNUMBER(F49),D49<F49),1,0)+IF(AND(ISNUMBER(D51),ISNUMBER(F51),D51<F51),1,0) | Q37: =IF(ISNUMBER(F46),F46,0)+IF(ISNUMBER(D49),D49,0)+IF(ISNUMBER(D51),D51,0) | R37: =IF(ISNUMBER(D46),D46,0)+IF(ISNUMBER(F49),F49,0)+IF(ISNUMBER(F51),F51,0) | S37: =P37-Q37 | T37: =M37*3+N37 | U37: =S37*100000000 + (R37+100)*100000 + P37*1000 + IFERROR(VLOOKUP(K37, RankingFIFA!$A$1:$B$48, 2, FALSE), 0)
C38: Alemania | D38: 2 | E38: - | F38: 1 | G38: Curaçao | H38: =IF(AND(ISNUMBER(D38),ISNUMBER(F38)),"Ok","") | I38: Domingo, 14 de junio 2026 - 11:00 | K38: F | L38: Suecia | M38: =IF(ISNUMBER(D47),1,0)+IF(ISNUMBER(F48),1,0)+IF(ISNUMBER(F51),1,0) | N38: =IF(AND(ISNUMBER(D47),ISNUMBER(F47),D47>F47),1,0)+IF(AND(ISNUMBER(F48),ISNUMBER(D48),F48>D48),1,0)+IF(AND(ISNUMBER(F51),ISNUMBER(D51),F51>D51),1,0) | O38: =IF(AND(ISNUMBER(D47),ISNUMBER(F47),D47=F47),1,0)+IF(AND(ISNUMBER(F48),ISNUMBER(D48),F48=D48),1,0)+IF(AND(ISNUMBER(F51),ISNUMBER(D51),F51=D51),1,0) | P38: =IF(AND(ISNUMBER(D47),ISNUMBER(F47),D47<F47),1,0)+IF(AND(ISNUMBER(F48),ISNUMBER(D48),F48<D48),1,0)+IF(AND(ISNUMBER(F51),ISNUMBER(D51),F51<D51),1,0) | Q38: =IF(ISNUMBER(D47),D47,0)+IF(ISNUMBER(F48),F48,0)+IF(ISNUMBER(F51),F51,0) | R38: =IF(ISNUMBER(F47),F47,0)+IF(ISNUMBER(D48),D48,0)+IF(ISNUMBER(D51),D51,0) | S38: =P38-Q38 | T38: =M38*3+N38 | U38: =S38*100000000 + (R38+100)*100000 + P38*1000 + IFERROR(VLOOKUP(K38, RankingFIFA!$A$1:$B$48, 2, FALSE), 0)
C39: Costa de Marfil | D39: 1 | E39: - | F39: 0 | G39: Ecuador | H39: =IF(AND(ISNUMBER(D39),ISNUMBER(F39)),"Ok","") | I39: Domingo, 14 de junio 2026 - 17:00 | K39: F | L39: Túnez | M39: =IF(ISNUMBER(F47),1,0)+IF(ISNUMBER(F49),1,0)+IF(ISNUMBER(D50),1,0) | N39: =IF(AND(ISNUMBER(F47),ISNUMBER(D47),F47>D47),1,0)+IF(AND(ISNUMBER(F49),ISNUMBER(D49),F49>D49),1,0)+IF(AND(ISNUMBER(D50),ISNUMBER(F50),D50>F50),1,0) | O39: =IF(AND(ISNUMBER(F47),ISNUMBER(D47),F47=D47),1,0)+IF(AND(ISNUMBER(F49),ISNUMBER(D49),F49=D49),1,0)+IF(AND(ISNUMBER(D50),ISNUMBER(F50),D50=F50),1,0) | P39: =IF(AND(ISNUMBER(F47),ISNUMBER(D47),F47<D47),1,0)+IF(AND(ISNUMBER(F49),ISNUMBER(D49),F49<D49),1,0)+IF(AND(ISNUMBER(D50),ISNUMBER(F50),D50<F50),1,0) | Q39: =IF(ISNUMBER(F47),F47,0)+IF(ISNUMBER(F49),F49,0)+IF(ISNUMBER(D50),D50,0) | R39: =IF(ISNUMBER(D47),D47,0)+IF(ISNUMBER(D49),D49,0)+IF(ISNUMBER(F50),F50,0) | S39: =P39-Q39 | T39: =M39*3+N39 | U39: =S39*100000000 + (R39+100)*100000 + P39*1000 + IFERROR(VLOOKUP(K39, RankingFIFA!$A$1:$B$48, 2, FALSE), 0)
C40: Alemania | D40: 1 | E40: - | F40: 2 | G40: Costa de Marfil | H40: =IF(AND(ISNUMBER(D40),ISNUMBER(F40)),"Ok","") | I40: Sábado, 20 de junio 2026 - 14:00
C41: Curaçao | D41: 0 | E41: - | F41: 2 | G41: Ecuador | H41: =IF(AND(ISNUMBER(D41),ISNUMBER(F41)),"Ok","") | I41: Viernes, 19 de junio 2026 - 14:00
C42: Ecuador | D42: 1 | E42: - | F42: 2 | G42: Alemania | H42: =IF(AND(ISNUMBER(D42),ISNUMBER(F42)),"Ok","") | I42: Jueves, 25 de junio 2026 - 14:00 | K42: G | L42: Bélgica | M42: =IF(ISNUMBER(D54),1,0)+IF(ISNUMBER(D56),1,0)+IF(ISNUMBER(F58),1,0) | N42: =IF(AND(ISNUMBER(D54),ISNUMBER(F54),D54>F54),1,0)+IF(AND(ISNUMBER(D56),ISNUMBER(F56),D56>F56),1,0)+IF(AND(ISNUMBER(F58),ISNUMBER(D58),F58>D58),1,0) | O42: =IF(AND(ISNUMBER(D54),ISNUMBER(F54),D54=F54),1,0)+IF(AND(ISNUMBER(D56),ISNUMBER(F56),D56=F56),1,0)+IF(AND(ISNUMBER(F58),ISNUMBER(D58),F58=D58),1,0) | P42: =IF(AND(ISNUMBER(D54),ISNUMBER(F54),D54<F54),1,0)+IF(AND(ISNUMBER(D56),ISNUMBER(F56),D56<F56),1,0)+IF(AND(ISNUMBER(F58),ISNUMBER(D58),F58<D58),1,0) | Q42: =IF(ISNUMBER(D54),D54,0)+IF(ISNUMBER(D56),D56,0)+IF(ISNUMBER(F58),F58,0) | R42: =IF(ISNUMBER(F54),F54,0)+IF(ISNUMBER(F56),F56,0)+IF(ISNUMBER(D58),D58,0) | S42: =P42-Q42 | T42: =M42*3+N42 | U42: =S42*100000000 + (R42+100)*100000 + P42*1000 + IFERROR(VLOOKUP(K42, RankingFIFA!$A$1:$B$48, 2, FALSE), 0)
C43: Curaçao | D43: 0 | E43: - | F43: 1 | G43: Costa de Marfil | H43: =IF(AND(ISNUMBER(D43),ISNUMBER(F43)),"Ok","") | I43: Miércoles, 24 de junio 2026 - 14:00 | K43: G | L43: Egipto | M43: =IF(ISNUMBER(F54),1,0)+IF(ISNUMBER(D57),1,0)+IF(ISNUMBER(D59),1,0) | N43: =IF(AND(ISNUMBER(F54),ISNUMBER(D54),F54>D54),1,0)+IF(AND(ISNUMBER(D57),ISNUMBER(F57),D57>F57),1,0)+IF(AND(ISNUMBER(D59),ISNUMBER(F59),D59>F59),1,0) | O43: =IF(AND(ISNUMBER(F54),ISNUMBER(D54),F54=D54),1,0)+IF(AND(ISNUMBER(D57),ISNUMBER(F57),D57=F57),1,0)+IF(AND(ISNUMBER(D59),ISNUMBER(F59),D59=F59),1,0) | P43: =IF(AND(ISNUMBER(F54),ISNUMBER(D54),F54<D54),1,0)+IF(AND(ISNUMBER(D57),ISNUMBER(F57),D57<F57),1,0)+IF(AND(ISNUMBER(D59),ISNUMBER(F59),D59<F59),1,0) | Q43: =IF(ISNUMBER(F54),F54,0)+IF(ISNUMBER(D57),D57,0)+IF(ISNUMBER(D59),D59,0) | R43: =IF(ISNUMBER(D54),D54,0)+IF(ISNUMBER(F57),F57,0)+IF(ISNUMBER(F59),F59,0) | S43: =P43-Q43 | T43: =M43*3+N43 | U43: =S43*100000000 + (R43+100)*100000 + P43*1000 + IFERROR(VLOOKUP(K43, RankingFIFA!$A$1:$B$48, 2, FALSE), 0)
...

Sheet Mejores Terceros
B2: RANKING DE MEJORES TERCEROS LUGARES
B5: Posición | C5: Grupo | D5: Equipo | E5: PTS | F5: DIF | G5: Clasifica a 16avos
B6: 1 | C6: =Backend!B16 | D6: =Backend!C16 | E6: =IF(D6="","",VLOOKUP(D6, Grupos!$K$6:$S$77, 9, FALSE)) | F6: =IF(D6="","",VLOOKUP(D6, Grupos!$K$6:$R$77, 8, FALSE)) | G6: =IF(Backend!C16="","",IF(1<=8, "✅ Avanza", "❌ Eliminado"))
B7: 2 | C7: =Backend!B17 | D7: =Backend!C17 | E7: =IF(D7="","",VLOOKUP(D7, Grupos!$K$6:$S$77, 9, FALSE)) | F7: =IF(D7="","",VLOOKUP(D7, Grupos!$K$6:$R$77, 8, FALSE)) | G7: =IF(Backend!C17="","",IF(2<=8, "✅ Avanza", "❌ Eliminado"))
B8: 3 | C8: =Backend!B18 | D8: =Backend!C18 | E8: =IF(D8="","",VLOOKUP(D8, Grupos!$K$6:$S$77, 9, FALSE)) | F8: =IF(D8="","",VLOOKUP(D8, Grupos!$K$6:$R$77, 8, FALSE)) | G8: =IF(Backend!C18="","",IF(3<=8, "✅ Avanza", "❌ Eliminado"))
B9: 4 | C9: =Backend!B19 | D9: =Backend!C19 | E9: =IF(D9="","",VLOOKUP(D9, Grupos!$K$6:$S$77, 9, FALSE)) | F9: =IF(D9="","",VLOOKUP(D9, Grupos!$K$6:$R$77, 8, FALSE)) | G9: =IF(Backend!C19="","",IF(4<=8, "✅ Avanza", "❌ Eliminado"))
B10: 5 | C10: =Backend!B20 | D10: =Backend!C20 | E10: =IF(D10="","",VLOOKUP(D10, Grupos!$K$6:$S$77, 9, FALSE)) | F10: =IF(D10="","",VLOOKUP(D10, Grupos!$K$6:$R$77, 8, FALSE)) | G10: =IF(Backend!C20="","",IF(5<=8, "✅ Avanza", "❌ Eliminado"))
B11: 6 | C11: =Backend!B21 | D11: =Backend!C21 | E11: =IF(D11="","",VLOOKUP(D11, Grupos!$K$6:$S$77, 9, FALSE)) | F11: =IF(D11="","",VLOOKUP(D11, Grupos!$K$6:$R$77, 8, FALSE)) | G11: =IF(Backend!C21="","",IF(6<=8, "✅ Avanza", "❌ Eliminado"))
B12: 7 | C12: =Backend!B22 | D12: =Backend!C22 | E12: =IF(D12="","",VLOOKUP(D12, Grupos!$K$6:$S$77, 9, FALSE)) | F12: =IF(D12="","",VLOOKUP(D12, Grupos!$K$6:$R$77, 8, FALSE)) | G12: =IF(Backend!C22="","",IF(7<=8, "✅ Avanza", "❌ Eliminado"))
B13: 8 | C13: =Backend!B23 | D13: =Backend!C23 | E13: =IF(D13="","",VLOOKUP(D13, Grupos!$K$6:$S$77, 9, FALSE)) | F13: =IF(D13="","",VLOOKUP(D13, Grupos!$K$6:$R$77, 8, FALSE)) | G13: =IF(Backend!C23="","",IF(8<=8, "✅ Avanza", "❌ Eliminado"))
B14: 9 | C14: =Backend!B24 | D14: =Backend!C24 | E14: =IF(D14="","",VLOOKUP(D14, Grupos!$K$6:$S$77, 9, FALSE)) | F14: =IF(D14="","",VLOOKUP(D14, Grupos!$K$6:$R$77, 8, FALSE)) | G14: =IF(Backend!C24="","",IF(9<=8, "✅ Avanza", "❌ Eliminado"))
B15: 10 | C15: =Backend!B25 | D15: =Backend!C25 | E15: =IF(D15="","",VLOOKUP(D15, Grupos!$K$6:$S$77, 9, FALSE)) | F15: =IF(D15="","",VLOOKUP(D15, Grupos!$K$6:$R$77, 8, FALSE)) | G15: =IF(Backend!C25="","",IF(10<=8, "✅ Avanza", "❌ Eliminado"))
B16: 11 | C16: =Backend!B26 | D16: =Backend!C26 | E16: =IF(D16="","",VLOOKUP(D16, Grupos!$K$6:$S$77, 9, FALSE)) | F16: =IF(D16="","",VLOOKUP(D16, Grupos!$K$6:$R$77, 8, FALSE)) | G16: =IF(Backend!C26="","",IF(11<=8, "✅ Avanza", "❌ Eliminado"))
B17: 12 | C17: =Backend!B27 | D17: =Backend!C27 | E17: =IF(D17="","",VLOOKUP(D17, Grupos!$K$6:$S$77, 9, FALSE)) | F17: =IF(D17="","",VLOOKUP(D17, Grupos!$K$6:$R$77, 8, FALSE)) | G17: =IF(Backend!C27="","",IF(12<=8, "✅ Avanza", "❌ Eliminado"))

Sheet Backend
A1: Grupo | B1: 1ro | C1: 2do | D1: 3ro | E1: 3ro Index
A2: A | B2: =INDEX(Grupos!$K$6:$K$9, MATCH(LARGE(Grupos!$T$6:$T$9, 1), Grupos!$T$6:$T$9, 0)) | C2: =INDEX(Grupos!$K$6:$K$9, MATCH(LARGE(Grupos!$T$6:$T$9, 2), Grupos!$T$6:$T$9, 0)) | D2: =INDEX(Grupos!$K$6:$K$9, MATCH(LARGE(Grupos!$T$6:$T$9, 3), Grupos!$T$6:$T$9, 0)) | E2: =LARGE(Grupos!$T$6:$T$9, 3)
A3: B | B3: =INDEX(Grupos!$K$12:$K$15, MATCH(LARGE(Grupos!$T$12:$T$15, 1), Grupos!$T$12:$T$15, 0)) | C3: =INDEX(Grupos!$K$12:$K$15, MATCH(LARGE(Grupos!$T$12:$T$15, 2), Grupos!$T$12:$T$15, 0)) | D3: =INDEX(Grupos!$K$12:$K$15, MATCH(LARGE(Grupos!$T$12:$T$15, 3), Grupos!$T$12:$T$15, 0)) | E3: =LARGE(Grupos!$T$12:$T$15, 3)
A4: C | B4: =INDEX(Grupos!$K$18:$K$21, MATCH(LARGE(Grupos!$T$18:$T$21, 1), Grupos!$T$18:$T$21, 0)) | C4: =INDEX(Grupos!$K$18:$K$21, MATCH(LARGE(Grupos!$T$18:$T$21, 2), Grupos!$T$18:$T$21, 0)) | D4: =INDEX(Grupos!$K$18:$K$21, MATCH(LARGE(Grupos!$T$18:$T$21, 3), Grupos!$T$18:$T$21, 0)) | E4: =LARGE(Grupos!$T$18:$T$21, 3)
A5: D | B5: =INDEX(Grupos!$K$24:$K$27, MATCH(LARGE(Grupos!$T$24:$T$27, 1), Grupos!$T$24:$T$27, 0)) | C5: =INDEX(Grupos!$K$24:$K$27, MATCH(LARGE(Grupos!$T$24:$T$27, 2), Grupos!$T$24:$T$27, 0)) | D5: =INDEX(Grupos!$K$24:$K$27, MATCH(LARGE(Grupos!$T$24:$T$27, 3), Grupos!$T$24:$T$27, 0)) | E5: =LARGE(Grupos!$T$24:$T$27, 3)
A6: E | B6: =INDEX(Grupos!$K$30:$K$33, MATCH(LARGE(Grupos!$T$30:$T$33, 1), Grupos!$T$30:$T$33, 0)) | C6: =INDEX(Grupos!$K$30:$K$33, MATCH(LARGE(Grupos!$T$30:$T$33, 2), Grupos!$T$30:$T$33, 0)) | D6: =INDEX(Grupos!$K$30:$K$33, MATCH(LARGE(Grupos!$T$30:$T$33, 3), Grupos!$T$30:$T$33, 0)) | E6: =LARGE(Grupos!$T$30:$T$33, 3)
A7: F | B7: =INDEX(Grupos!$K$36:$K$39, MATCH(LARGE(Grupos!$T$36:$T$39, 1), Grupos!$T$36:$T$39, 0)) | C7: =INDEX(Grupos!$K$36:$K$39, MATCH(LARGE(Grupos!$T$36:$T$39, 2), Grupos!$T$36:$T$39, 0)) | D7: =INDEX(Grupos!$K$36:$K$39, MATCH(LARGE(Grupos!$T$36:$T$39, 3), Grupos!$T$36:$T$39, 0)) | E7: =LARGE(Grupos!$T$36:$T$39, 3)
A8: G | B8: =INDEX(Grupos!$K$42:$K$45, MATCH(LARGE(Grupos!$T$42:$T$45, 1), Grupos!$T$42:$T$45, 0)) | C8: =INDEX(Grupos!$K$42:$K$45, MATCH(LARGE(Grupos!$T$42:$T$45, 2), Grupos!$T$42:$T$45, 0)) | D8: =INDEX(Grupos!$K$42:$K$45, MATCH(LARGE(Grupos!$T$42:$T$45, 3), Grupos!$T$42:$T$45, 0)) | E8: =LARGE(Grupos!$T$42:$T$45, 3)
A9: H | B9: =INDEX(Grupos!$K$48:$K$51, MATCH(LARGE(Grupos!$T$48:$T$51, 1), Grupos!$T$48:$T$51, 0)) | C9: =INDEX(Grupos!$K$48:$K$51, MATCH(LARGE(Grupos!$T$48:$T$51, 2), Grupos!$T$48:$T$51, 0)) | D9: =INDEX(Grupos!$K$48:$K$51, MATCH(LARGE(Grupos!$T$48:$T$51, 3), Grupos!$T$48:$T$51, 0)) | E9: =LARGE(Grupos!$T$48:$T$51, 3)
A10: I | B10: =INDEX(Grupos!$K$54:$K$57, MATCH(LARGE(Grupos!$T$54:$T$57, 1), Grupos!$T$54:$T$57, 0)) | C10: =INDEX(Grupos!$K$54:$K$57, MATCH(LARGE(Grupos!$T$54:$T$57, 2), Grupos!$T$54:$T$57, 0)) | D10: =INDEX(Grupos!$K$54:$K$57, MATCH(LARGE(Grupos!$T$54:$T$57, 3), Grupos!$T$54:$T$57, 0)) | E10: =LARGE(Grupos!$T$54:$T$57, 3)
A11: J | B11: =INDEX(Grupos!$K$60:$K$63, MATCH(LARGE(Grupos!$T$60:$T$63, 1), Grupos!$T$60:$T$63, 0)) | C11: =INDEX(Grupos!$K$60:$K$63, MATCH(LARGE(Grupos!$T$60:$T$63, 2), Grupos!$T$60:$T$63, 0)) | D11: =INDEX(Grupos!$K$60:$K$63, MATCH(LARGE(Grupos!$T$60:$T$63, 3), Grupos!$T$60:$T$63, 0)) | E11: =LARGE(Grupos!$T$60:$T$63, 3)
A12: K | B12: =INDEX(Grupos!$K$66:$K$69, MATCH(LARGE(Grupos!$T$66:$T$69, 1), Grupos!$T$66:$T$69, 0)) | C12: =INDEX(Grupos!$K$66:$K$69, MATCH(LARGE(Grupos!$T$66:$T$69, 2), Grupos!$T$66:$T$69, 0)) | D12: =INDEX(Grupos!$K$66:$K$69, MATCH(LARGE(Grupos!$T$66:$T$69, 3), Grupos!$T$66:$T$69, 0)) | E12: =LARGE(Grupos!$T$66:$T$69, 3)
A13: L | B13: =INDEX(Grupos!$K$72:$K$75, MATCH(LARGE(Grupos!$T$72:$T$75, 1), Grupos!$T$72:$T$75, 0)) | C13: =INDEX(Grupos!$K$72:$K$75, MATCH(LARGE(Grupos!$T$72:$T$75, 2), Grupos!$T$72:$T$75, 0)) | D13: =INDEX(Grupos!$K$72:$K$75, MATCH(LARGE(Grupos!$T$72:$T$75, 3), Grupos!$T$72:$T$75, 0)) | E13: =LARGE(Grupos!$T$72:$T$75, 3)
B14: =B5 | C14: =INDEX($C$16:$C$23, MATCH(VLOOKUP($D$25, MatrizTerceros!$A$1:$I$495, 4, FALSE), $B$16:$B$23, 0))
A15: Rank | B15: Grupo 3ro | C15: Equipo 3ro
A16: =LARGE($E$2:$E$13, 1) | B16: =INDEX($A$2:$A$13, MATCH(A16, $E$2:$E$13, 0)) | C16: =INDEX($D$2:$D$13, MATCH(A16, $E$2:$E$13, 0))
A17: =LARGE($E$2:$E$13, 2) | B17: =INDEX($A$2:$A$13, MATCH(A17, $E$2:$E$13, 0)) | C17: =INDEX($D$2:$D$13, MATCH(A17, $E$2:$E$13, 0))
A18: =LARGE($E$2:$E$13, 3) | B18: =INDEX($A$2:$A$13, MATCH(A18, $E$2:$E$13, 0)) | C18: =INDEX($D$2:$D$13, MATCH(A18, $E$2:$E$13, 0))
A19: =LARGE($E$2:$E$13, 4) | B19: =INDEX($A$2:$A$13, MATCH(A19, $E$2:$E$13, 0)) | C19: =INDEX($D$2:$D$13, MATCH(A19, $E$2:$E$13, 0))
A20: =LARGE($E$2:$E$13, 5) | B20: =INDEX($A$2:$A$13, MATCH(A20, $E$2:$E$13, 0)) | C20: =INDEX($D$2:$D$13, MATCH(A20, $E$2:$E$13, 0))
A21: =LARGE($E$2:$E$13, 6) | B21: =INDEX($A$2:$A$13, MATCH(A21, $E$2:$E$13, 0)) | C21: =INDEX($D$2:$D$13, MATCH(A21, $E$2:$E$13, 0))
A22: =LARGE($E$2:$E$13, 7) | B22: =INDEX($A$2:$A$13, MATCH(A22, $E$2:$E$13, 0)) | C22: =INDEX($D$2:$D$13, MATCH(A22, $E$2:$E$13, 0))
A23: =LARGE($E$2:$E$13, 8) | B23: =INDEX($A$2:$A$13, MATCH(A23, $E$2:$E$13, 0)) | C23: =INDEX($D$2:$D$13, MATCH(A23, $E$2:$E$13, 0))
A24: =LARGE($E$2:$E$13, 9) | B24: =INDEX($A$2:$A$13, MATCH(A24, $E$2:$E$13, 0)) | C24: =INDEX($D$2:$D$13, MATCH(A24, $E$2:$E$13, 0))
A25: =LARGE($E$2:$E$13, 10) | B25: =INDEX($A$2:$A$13, MATCH(A25, $E$2:$E$13, 0)) | C25: =INDEX($D$2:$D$13, MATCH(A25, $E$2:$E$13, 0)) | D25: =""&IF(COUNTIF($B$16:$B$23,"A"),"A","")&IF(COUNTIF($B$16:$B$23,"B"),"B","")&IF(COUNTIF($B$16:$B$23,"C"),"C","")&IF(COUNTIF($B$16:$B$23,"D"),"D","")&IF(COUNTIF($B$16:$B$23,"E"),"E","")&IF(COUNTIF($B$16:$B$23,"F"),"F","")&IF(COUNTIF($B$16:$B$23,"G"),"G","")&IF(COUNTIF($B$16:$B$23,"H"),"H","")&IF(COUNTIF($B$16:$B$23,"I"),"I","")&IF(COUNTIF($B$16:$B$23,"J"),"J","")&IF(COUNTIF($B$16:$B$23,"K"),"K","")&IF(COUNTIF($B$16:$B$23,"L"),"L","")
A26: =LARGE($E$2:$E$13, 11) | B26: =INDEX($A$2:$A$13, MATCH(A26, $E$2:$E$13, 0)) | C26: =INDEX($D$2:$D$13, MATCH(A26, $E$2:$E$13, 0))
A27: =LARGE($E$2:$E$13, 12) | B27: =INDEX($A$2:$A$13, MATCH(A27, $E$2:$E$13, 0)) | C27: =INDEX($D$2:$D$13, MATCH(A27, $E$2:$E$13, 0))
A29: M# | B29: Team 1 | C29: Combo 3ros: | D29: =""&IF(COUNTIF($B$16:$B$23,"A"),"A","")&IF(COUNTIF($B$16:$B$23,"B"),"B","")&IF(COUNTIF($B$16:$B$23,"C"),"C","")&IF(COUNTIF($B$16:$B$23,"D"),"D","")&IF(COUNTIF($B$16:$B$23,"E"),"E","")&IF(COUNTIF($B$16:$B$23,"F"),"F","")&IF(COUNTIF($B$16:$B$23,"G"),"G","")&IF(COUNTIF($B$16:$B$23,"H"),"H","")&IF(COUNTIF($B$16:$B$23,"I"),"I","")&IF(COUNTIF($B$16:$B$23,"J"),"J","")&IF(COUNTIF($B$16:$B$23,"K"),"K","")&IF(COUNTIF($B$16:$B$23,"L"),"L","")

Sheet Eliminatorias
A1: FASE FINAL (ELIMINACIÓN DIRECTA)
A4: DIECISEISAVOS DE FINAL (Ronda de 32)
A5: Partido | B5: Equipo A | C5: Goles | D5: Pen. | E5: vs | F5: Pen. | G5: Goles | H5: Equipo B | I5: Clasifica | J5: Fecha y Estadio
A6: 1/16 - P1 | B6: =Backend!C2 | C6: 1 | E6: - | G6: 0 | H6: =Backend!C3 | I6: =IF(OR(C6="", G6=""), "", IF(C6>G6, B6, IF(G6>C6, H6, IF(D6>F6, B6, IF(F6>D6, H6, "Faltan Penales"))))) | J6: Domingo, 28 de junio 2026 - Estadio Los Ángeles
A7: 1/16 - P2 | B7: =Backend!B7 | C7: 2 | E7: - | G7: 0 | H7: =Backend!C4 | I7: =IF(OR(C7="", G7=""), "", IF(C7>G7, B7, IF(G7>C7, H7, IF(D7>F7, B7, IF(F7>D7, H7, "Faltan Penales"))))) | J7: Lunes, 29 de junio 2026 - Estadio Boston
A8: 1/16 - P3 | B8: =Backend!B6 | C8: 0 | E8: - | G8: 2 | H8: =IFERROR(INDEX(Backend!$C$16:$C$23, MATCH(VLOOKUP(Backend!$D$29, MatrizTerceros!$A$1:$I$495, 5, FALSE), Backend!$B$16:$B$23, 0)), "") | I8: =IF(OR(C8="", G8=""), "", IF(C8>G8, B8, IF(G8>C8, H8, IF(D8>F8, B8, IF(F8>D8, H8, "Faltan Penales"))))) | J8: Lunes, 29 de junio 2026 - Estadio Monterrey
A9: 1/16 - P4 | B9: =Backend!B10 | C9: 0 | E9: - | G9: 3 | H9: =IFERROR(INDEX(Backend!$C$16:$C$23, MATCH(VLOOKUP(Backend!$D$29, MatrizTerceros!$A$1:$I$495, 7, FALSE), Backend!$B$16:$B$23, 0)), "") | I9: =IF(OR(C9="", G9=""), "", IF(C9>G9, B9, IF(G9>C9, H9, IF(D9>F9, B9, IF(F9>D9, H9, "Faltan Penales"))))) | J9: Lunes, 29 de junio 2026 - Estadio Houston
A10: 1/16 - P5 | B10: =Backend!B4 | C10: 0 | E10: - | G10: 2 | H10: =Backend!C7 | I10: =IF(OR(C10="", G10=""), "", IF(C10>G10, B10, IF(G10>C10, H10, IF(D10>F10, B10, IF(F10>D10, H10, "Faltan Penales"))))) | J10: Martes, 30 de junio 2026 - Estadio Nueva York Nueva Jersey
A11: 1/16 - P6 | B11: =Backend!C6 | C11: 1 | E11: - | G11: 0 | H11: =Backend!C10 | I11: =IF(OR(C11="", G11=""), "", IF(C11>G11, B11, IF(G11>C11, H11, IF(D11>F11, B11, IF(F11>D11, H11, "Faltan Penales"))))) | J11: Martes, 30 de junio 2026 - Estadio Dallas
A12: 1/16 - P7 | B12: =Backend!B2 | C12: 0 | E12: - | G12: 3 | H12: =IFERROR(INDEX(Backend!$C$16:$C$23, MATCH(VLOOKUP(Backend!$D$29, MatrizTerceros!$A$1:$I$495, 2, FALSE), Backend!$B$16:$B$23, 0)), "") | I12: =IF(OR(C12="", G12=""), "", IF(C12>G12, B12, IF(G12>C12, H12, IF(D12>F12, B12, IF(F12>D12, H12, "Faltan Penales"))))) | J12: Martes, 30 de junio 2026 - Estadio Ciudad de México
A13: 1/16 - P8 | B13: =Backend!B13 | C13: 1 | E13: - | G13: 2 | H13: =IFERROR(INDEX(Backend!$C$16:$C$23, MATCH(VLOOKUP(Backend!$D$29, MatrizTerceros!$A$1:$I$495, 9, FALSE), Backend!$B$16:$B$23, 0)), "") | I13: =IF(OR(C13="", G13=""), "", IF(C13>G13, B13, IF(G13>C13, H13, IF(D13>F13, B13, IF(F13>D13, H13, "Faltan Penales"))))) | J13: Miércoles, 1 de julio 2026 - Estadio Atlanta
A14: 1/16 - P9 | B14: =Backend!B5 | C14: 2 | E14: - | G14: 1 | H14: =IFERROR(INDEX(Backend!$C$16:$C$23, MATCH(VLOOKUP(Backend!$D$29, MatrizTerceros!$A$1:$I$495, 4, FALSE), Backend!$B$16:$B$23, 0)), "") | I14: =IF(OR(C14="", G14=""), "", IF(C14>G14, B14, IF(G14>C14, H14, IF(D14>F14, B14, IF(F14>D14, H14, "Faltan Penales"))))) | J14: Miércoles, 1 de julio 2026 - Estadio Bahía de San Francisco
A15: 1/16 - P10 | B15: =Backend!B8 | C15: 3 | E15: - | G15: 0 | H15: =IFERROR(INDEX(Backend!$C$16:$C$23, MATCH(VLOOKUP(Backend!$D$29, MatrizTerceros!$A$1:$I$495, 6, FALSE), Backend!$B$16:$B$23, 0)), "") | I15: =IF(OR(C15="", G15=""), "", IF(C15>G15, B15, IF(G15>C15, H15, IF(D15>F15, B15, IF(F15>D15, H15, "Faltan Penales"))))) | J15: Miércoles, 1 de julio 2026 - Estadio Seattle
A16: 1/16 - P11 | B16: =Backend!C12 | C16: 1 | E16: - | G16: 2 | H16: =Backend!C13 | I16: =IF(OR(C16="", G16=""), "", IF(C16>G16, B16, IF(G16>C16, H16, IF(D16>F16, B16, IF(F16>D16, H16, "Faltan Penales"))))) | J16: Jueves, 2 de julio 2026 - Estadio Toronto
A17: 1/16 - P12 | B17: =Backend!B9 | C17: 0 | E17: - | G17: 2 | H17: =Backend!C11 | I17: =IF(OR(C17="", G17=""), "", IF(C17>G17, B17, IF(G17>C17, H17, IF(D17>F17, B17, IF(F17>D17, H17, "Faltan Penales"))))) | J17: Jueves, 2 de julio 2026 - Estadio Los Ángeles
A18: 1/16 - P13 | B18: =Backend!B3 | C18: 0 | E18: - | G18: 2 | H18: =IFERROR(INDEX(Backend!$C$16:$C$23, MATCH(VLOOKUP(Backend!$D$29, MatrizTerceros!$A$1:$I$495, 3, FALSE), Backend!$B$16:$B$23, 0)), "") | I18: =IF(OR(C18="", G18=""), "", IF(C18>G18, B18, IF(G18>C18, H18, IF(D18>F18, B18, IF(F18>D18, H18, "Faltan Penales"))))) | J18: Jueves, 2 de julio 2026 - Estadio BC Place Vancouver
A19: 1/16 - P14 | B19: =Backend!B12 | C19: 1 | E19: - | G19: 3 | H19: =IFERROR(INDEX(Backend!$C$16:$C$23, MATCH(VLOOKUP(Backend!$D$29, MatrizTerceros!$A$1:$I$495, 8, FALSE), Backend!$B$16:$B$23, 0)), "") | I19: =IF(OR(C19="", G19=""), "", IF(C19>G19, B19, IF(G19>C19, H19, IF(D19>F19, B19, IF(F19>D19, H19, "Faltan Penales"))))) | J19: Viernes, 3 de julio 2026 - Estadio Miami
A20: 1/16 - P15 | B20: =Backend!B11 | C20: 0 | E20: - | G20: 2 | H20: =Backend!C9 | I20: =IF(OR(C20="", G20=""), "", IF(C20>G20, B20, IF(G20>C20, H20, IF(D20>F20, B20, IF(F20>D20, H20, "Faltan Penales"))))) | J20: Viernes, 3 de julio 2026 - Estadio Kansas City
A21: 1/16 - P16 | B21: =Backend!C5 | C21: 0 | E21: - | G21: 1 | H21: =Backend!C8 | I21: =IF(OR(C21="", G21=""), "", IF(C21>G21, B21, IF(G21>C21, H21, IF(D21>F21, B21, IF(F21>D21, H21, "Faltan Penales"))))) | J21: Viernes, 3 de julio 2026 - Estadio Dallas
A23: OCTAVOS DE FINAL
A25: 1/8 - P1 | B25: =I6 | C25: 0 | E25: - | G25: 1 | H25: =I7 | I25: =IF(OR(C25="", G25=""), "", IF(C25>G25, B25, IF(G25>C25, H25, IF(D25>F25, B25, IF(F25>D25, H25, "Faltan Penales"))))) | J25: Sábado, 4 de julio 2026 - Estadio Filadelfia
A26: 1/8 - P2 | B26: =I8 | C26: 0 | E26: - | G26: 4 | H26: =I9 | I26: =IF(OR(C26="", G26=""), "", IF(C26>G26, B26, IF(G26>C26, H26, IF(D26>F26, B26, IF(F26>D26, H26, "Faltan Penales"))))) | J26: Sábado, 4 de julio 2026 - Estadio Houston
A27: 1/8 - P3 | B27: =I10 | C27: 0 | E27: - | G27: 1 | H27: =I11 | I27: =IF(OR(C27="", G27=""), "", IF(C27>G27, B27, IF(G27>C27, H27, IF(D27>F27, B27, IF(F27>D27, H27, "Faltan Penales"))))) | J27: Domingo, 5 de julio 2026 - Estadio Nueva York Nueva Jersey
A28: 1/8 - P4 | B28: =I12 | C28: 0 | E28: - | G28: 2 | H28: =I13 | I28: =IF(OR(C28="", G28=""), "", IF(C28>G28, B28, IF(G28>C28, H28, IF(D28>F28, B28, IF(F28>D28, H28, "Faltan Penales"))))) | J28: Domingo, 5 de julio 2026 - Estadio Ciudad de México
A29: 1/8 - P5 | B29: =I14 | C29: 3 | E29: - | G29: 0 | H29: =I15 | I29: =IF(OR(C29="", G29=""), "", IF(C29>G29, B29, IF(G29>C29, H29, IF(D29>F29, B29, IF(F29>D29, H29, "Faltan Penales"))))) | J29: Lunes, 6 de julio 2026 - Estadio Dallas
A30: 1/8 - P6 | B30: =I16 | C30: 1 | E30: - | G30: 4 | H30: =I17 | I30: =IF(OR(C30="", G30=""), "", IF(C30>G30, B30, IF(G30>C30, H30, IF(D30>F30, B30, IF(F30>D30, H30, "Faltan Penales"))))) | J30: Lunes, 6 de julio 2026 - Estadio Seattle
A31: 1/8 - P7 | B31: =I18 | C31: 0 | E31: - | G31: 4 | H31: =I19 | I31: =IF(OR(C31="", G31=""), "", IF(C31>G31, B31, IF(G31>C31, H31, IF(D31>F31, B31, IF(F31>D31, H31, "Faltan Penales"))))) | J31: Martes, 7 de julio 2026 - Estadio Atlanta
A32: 1/8 - P8 | B32: =I20 | C32: 3 | E32: - | G32: 1 | H32: =I21 | I32: =IF(OR(C32="", G32=""), "", IF(C32>G32, B32, IF(G32>C32, H32, IF(D32>F32, B32, IF(F32>D32, H32, "Faltan Penales"))))) | J32: Martes, 7 de julio 2026 - Estadio BC Place Vancouver
A35: CUARTOS DE FINAL
A36: Partido | B36: Equipo A | C36: Goles | E36: vs | G36: Goles | H36: Equipo B | I36: Clasifica | J36: Fecha y Estadio
A37: 1/4 - P1 | B37: =I25 | C37: 0 | E37: - | G37: 3 | H37: =I26 | I37: =IF(OR(C37="", G37=""), "", IF(C37>G37, B37, IF(G37>C37, H37, IF(D37>F37, B37, IF(F37>D37, H37, "Faltan Penales"))))) | J37: Jueves, 9 de julio 2026 - Estadio Boston
A38: 1/4 - P2 | B38: =I27 | C38: 3 | E38: - | G38: 0 | H38: =I28 | I38: =IF(OR(C38="", G38=""), "", IF(C38>G38, B38, IF(G38>C38, H38, IF(D38>F38, B38, IF(F38>D38, H38, "Faltan Penales"))))) | J38: Viernes, 10 de julio 2026 - Estadio Los Ángeles
A39: 1/4 - P3 | B39: =I29 | C39: 4 | E39: - | G39: 1 | H39: =I30 | I39: =IF(OR(C39="", G39=""), "", IF(C39>G39, B39, IF(G39>C39, H39, IF(D39>F39, B39, IF(F39>D39, H39, "Faltan Penales"))))) | J39: Sábado, 11 de julio 2026 - Estadio Miami
A40: 1/4 - P4 | B40: =I31 | C40: 2 | E40: - | G40: 1 | H40: =I32 | I40: =IF(OR(C40="", G40=""), "", IF(C40>G40, B40, IF(G40>C40, H40, IF(D40>F40, B40, IF(F40>D40, H40, "Faltan Penales"))))) | J40: Sábado, 11 de julio 2026 - Estadio Kansas City
A43: SEMIFINALES
A44: Partido | B44: Equipo A | C44: Goles | E44: vs | G44: Goles | H44: Equipo B | I44: Clasifica | J44: Fecha y Estadio
A45: Semi - P1 | B45: =I37 | C45: 1 | E45: - | G45: 2 | H45: =I38 | I45: =IF(OR(C45="", G45=""), "", IF(C45>G45, B45, IF(G45>C45, H45, IF(D45>F45, B45, IF(F45>D45, H45, "Faltan Penales"))))) | J45: Martes, 14 de julio 2026 - Estadio Dallas
A46: Semi - P2 | B46: =I39 | C46: 0 | E46: - | G46: 2 | H46: =I40 | I46: =IF(OR(C46="", G46=""), "", IF(C46>G46, B46, IF(G46>C46, H46, IF(D46>F46, B46, IF(F46>D46, H46, "Faltan Penales"))))) | J46: Miércoles, 15 de julio 2026 - Estadio Atlanta
A49: PARTIDO POR EL TERCER LUGAR
A50: Partido | B50: Equipo A | C50: Goles | E50: vs | G50: Goles | H50: Equipo B | I50: Clasifica | J50: Fecha y Estadio
...

Sheet Calendario de Juegos
B2: Fase de grupos: calendario y horarios de la Copa Mundial de la FIFA 2026™
B4: Todos los horarios son de la Ciudad de México.
B5: Jueves, 11 de junio 2026
B6: 13:00 - México v Sudáfrica – Grupo A - Estadio Ciudad de México
B7: 20:00 - República de Corea v República Checa – Grupo A - Estadio Guadalajara
B9: Viernes, 12 de junio 2026
B10: 13:00 - Canadá v Bosnia y Herzegovina – Grupo B - Estadio Toronto
B11: 19:00 - Estados Unidos v Paraguay – Grupo D - Estadio Los Ángeles
B13: Sábado, 13 de junio 2026
B14: 13:00 - Catar v Suiza – Grupo B - Estadio Bahía de San Francisco
B15: 16:00 - Brasil v Marruecos – Grupo C - Estadio Nueva York Nueva Jersey
B16: 19:00 - Haití v Escocia – Grupo C - Estadio Boston
... B183: Partido 104 – Ganador Partido 101 v Ganador Partido 102 - Estadio Nueva York Nueva Jersey

Sheet Calendario 2
B2: Link para descargar archvivo ICS del Calendario Mundial 2026 para Outlook o iPhone:
B3: https://calendar.google.com/calendar/ical/611d68120c62daa60625df08296c3333f1416dbeb64241045a3c75dd62f175d8%40group.calendar.google.com/public/basic.ics
B6: Calendario para Google Calendar
B8: https://calendar.google.com/calendar/u/4?cid=NjExZDY4MTIwYzYyZGFhNjA2MjVkZjA4Mjk2YzMzMzNmMTQxNmRiZWI2NDI0MTA0NWEzYzc1ZGQ2MmYxNzVkOEBncm91cC5jYWxlbmRhci5nb29nbGUuY29t

Sheet RankingFIFA
A1: México | B1: 1000
A2: Sudáfrica | B2: 1000
A3: Corea del Sur | B3: 1000
A4: Chequia | B4: 1000
A5: Canadá | B5: 1000
A6: Bosnia y Herze. | B6: 1000
A7: Qatar | B7: 1000
A8: Suiza | B8: 1000
A9: Brasil | B9: 1000
A10: Marruecos | B10: 1000
A11: Haití | B11: 1000
A12: Escocia | B12: 1000
... A48: Panamá | B48: 1000

Sheet MatrizTerceros
A1: ABCDEFGH | B1: C | C1: E | D1: B | E1: F | F1: A | G1: G | H1: D | I1: H
A2: ABCDEFGI | B2: C | C2: E | D2: B | E2: F | F2: A | G2: G | H2: D | I2: I
A3: ABCDEFGJ | B3: C | C3: E | D3: B | E3: F | F3: A | G3: G | H3: D | I3: J
A4: ABCDEFGK | B4: C | C4: E | D4: B | E4: F | F4: A | G4: G | H4: D | I4: K
A5: ABCDEFGL | B5: C | C5: F | D5: B | E5: D | F5: A | G5: G | H5: L | I5: E
A6: ABCDEFHI | B6: C | C6: E | D6: B | E6: A | F6: H | G6: F | H6: D | I6: I
A7: ABCDEFHJ | B7: C | C7: E | D7: B | E7: A | F7: H | G7: F | H7: D | I7: J
A8: ABCDEFHK | B8: C | C8: E | D8: B | E8: A | F8: H | G8: F | H8: D | I8: K
A9: ABCDEFHL | B9: C | C9: E | D9: B | E9: D | F9: A | G9: F | H9: L | I9: H
A10: ABCDEFIJ | B10: C | C10: E | D10: B | E10: A | F10: I | G10: F | H10: D | I10: J
A11: ABCDEFIK | B11: C | C11: E | D11: B | E11: A | F11: I | G11: F | H11: D | I11: K
A12: ABCDEFIL | B12: C | C12: E | D12: B | E12: D | F12: A | G12: F | H12: L | I12: I
... A495: EFGHIJKL | B495: E | C495: G | D495: I | E495: F | F495: J | G495: H | H495: L | I495: K

Sheet Ranking FIFA
A1: Posición | B1: Selección | C1: Código | D1: Puntos Totales | E1: Puntos Anteriores | F1: Diferencia de Puntos (+/-) | G1: Cambio de Puesto | H1: Confederación
A2: 1 | B2: Francia | C2: FRA | D2: 1877.32 | E2: 1870 | F2: 7.32 | G2: ▲ +2 | H2: UEFA
A3: 2 | B3: España | C3: ESP | D3: 1876.4 | E3: 1877.18 | F3: -0.78 | G3: ▼ -1 | H3: UEFA
A4: 3 | B4: Argentina | C4: ARG | D4: 1874.81 | E4: 1873.33 | F4: 1.48 | G4: ▼ -1 | H4: CONMEBOL
A5: 4 | B5: Inglaterra | C5: ENG | D5: 1825.97 | E5: 1834.12 | F5: -8.15 | G5: = | H5: UEFA
A6: 5 | B6: Portugal | C6: POR | D6: 1763.83 | E6: 1760.38 | F6: 3.45 | G6: ▲ +1 | H6: UEFA
A7: 6 | B7: Brasil | C7: BRA | D7: 1761.16 | E7: 1760.46 | F7: 0.7 | G7: ▼ -1 | H7: CONMEBOL
A8: 7 | B8: Países Bajos | C8: NED | D8: 1757.87 | E8: 1756.27 | F8: 1.6 | G8: = | H8: UEFA
A9: 8 | B9: Marruecos | C9: MAR | D9: 1755.87 | E9: 1736.57 | F9: 19.3 | G9: = | H9: CAF
A10: 9 | B10: Bélgica | C10: BEL | D10: 1734.71 | E10: 1730.71 | F10: 4 | G10: = | H10: UEFA
A11: 10 | B11: Alemania | C11: GER | D11: 1730.37 | E11: 1724.15 | F11: 6.22 | G11: = | H11: UEFA
A12: 11 | B12: Croacia | C12: CRO | D12: 1717.07 | E12: 1716.88 | F12: 0.19 | G12: = | H12: UEFA
A13: 12 | B13: Italia | C13: ITA | D13: 1700.37 | E13: 1702.06 | F13: -1.69 | G13: ▲ +1 | H13: UEFA
... A212: 211 | B212: San Marino | C212: SMR | D212: 726.33 | E212: 726.03 | F212: 0.3 | G212: ▼ -1 | H212: UEFA
